{
 "cells": [
  {
   "cell_type": "markdown",
   "metadata": {},
   "source": [
    "## Transfer learning"
   ]
  },
  {
   "cell_type": "code",
   "execution_count": null,
   "metadata": {},
   "outputs": [
    {
     "ename": "",
     "evalue": "",
     "output_type": "error",
     "traceback": [
      "\u001b[1;31mFailed to start the Kernel. \n",
      "Traceback (most recent call last):\n",
      "  File \"/home/samin/.vscode/extensions/ms-toolsai.jupyter-2022.5.1001601848/pythonFiles/vscode_datascience_helpers/jupyter_daemon.py\", line 158, in _start_notebook\n",
      "    from notebook import notebookapp as app\n",
      "  File \"/home/samin/.local/lib/python3.8/site-packages/notebook/notebookapp.py\", line 79, in <module>\n",
      "    from .services.contents.manager import ContentsManager\n",
      "  File \"/home/samin/.local/lib/python3.8/site-packages/notebook/services/contents/manager.py\", line 17, in <module>\n",
      "    from nbformat import sign, validate as validate_nb, ValidationError\n",
      "  File \"/home/samin/.local/lib/python3.8/site-packages/nbformat/sign.py\", line 26, in <module>\n",
      "    from traitlets import (\n",
      "ImportError: cannot import name 'Callable' from 'traitlets' (/usr/lib/python3/dist-packages/traitlets/__init__.py)\n",
      "\n",
      "During handling of the above exception, another exception occurred:\n",
      "\n",
      "Traceback (most recent call last):\n",
      "  File \"/home/samin/.vscode/extensions/ms-toolsai.jupyter-2022.5.1001601848/pythonFiles/vscode_datascience_helpers/daemon/daemon_python.py\", line 54, in _decorator\n",
      "    return func(self, *args, **kwargs)\n",
      "  File \"/home/samin/.vscode/extensions/ms-toolsai.jupyter-2022.5.1001601848/pythonFiles/vscode_datascience_helpers/jupyter_daemon.py\", line 111, in m_exec_module_observable\n",
      "    self._start_notebook(args, cwd, env)\n",
      "  File \"/home/samin/.vscode/extensions/ms-toolsai.jupyter-2022.5.1001601848/pythonFiles/vscode_datascience_helpers/jupyter_daemon.py\", line 160, in _start_notebook\n",
      "    from notebook import app as app\n",
      "ImportError: cannot import name 'app' from 'notebook' (/home/samin/.local/lib/python3.8/site-packages/notebook/__init__.py)\n",
      "\n",
      "Failed to run jupyter as observable with args notebook --no-browser --notebook-dir=\"/home/introcept/Documents/mine/practice\" --config=/tmp/f961a8d3-8b20-42bf-8506-99a7e4cf8eac/jupyter_notebook_config.py --NotebookApp.iopub_data_rate_limit=10000000000.0. \n",
      "View Jupyter <a href='command:jupyter.viewOutput'>log</a> for further details."
     ]
    }
   ],
   "source": [
    "print(2+2)"
   ]
  },
  {
   "cell_type": "markdown",
   "metadata": {},
   "source": [
    "tf.k"
   ]
  }
 ],
 "metadata": {
  "kernelspec": {
   "display_name": "Python 3.8.10 ('dlenv': venv)",
   "language": "python",
   "name": "python3"
  },
  "language_info": {
   "name": "python",
   "version": "3.8.10"
  },
  "orig_nbformat": 4,
  "vscode": {
   "interpreter": {
    "hash": "6ed099af7b950fed84ff28bb4d4e670b2d45ec2b3a551ef89cd9c17ed482e4f7"
   }
  }
 },
 "nbformat": 4,
 "nbformat_minor": 2
}
